<?xml version="1.0" ?>
<!-- =================================================================================== -->
<!-- |    This document was autogenerated by xacro from vulcano_robot.urdf.xacro       | -->
<!-- |    EDITING THIS FILE BY HAND IS NOT RECOMMENDED                                 | -->
<!-- =================================================================================== -->
<robot name="vulcano" xmlns:xacro="http://www.ros.org/wiki/xacro">
  <!-- ***************** -->
  <!-- Imported elements -->
  <!-- ***************** -->
  <!-- First we import all posible elements defined in the urdf.xacro files. All these elements are defined as macro:xacros -->
  <gazebo reference="base_footprint">
    <material>Gazebo/Green</material>
  </gazebo>
  <!-- in kg-->
  <!-- This file unifies all sensors that can be used on simulation, defined as xacro:macros -->
  <!--material name="aluminum">
    <color rgba="0.5 0.5 0.5 1"/>
  </material-->
  <!-- x,y,z in translation from base_link to the center of the wheel -->
  <!-- *************** -->
  <!-- Robots Elements -->
  <!-- *************** -->
  <!-- Here we create the robot elements using the xacro:macros imported at the beggining of this file -->
  <!-- ***************** -->
  <!-- Imported elements -->
  <!-- ***************** -->
  <!-- First we import all posible elements defined in the urdf.xacro files. All these elements are defined as macro:xacros -->
  <!--
  Author: Kelsey Hawkins
  Contributers: Jimmy Da Silva, Ajit Krisshna N L, Muhammad Asif Rana
-->
  <!-- measured from model -->
  <!--<xacro:include filename="$(find ur_description)/urdf/common.gazebo.xacro"/>-->
  <link name="base_footprint">
    <visual>
      <origin rpy="0 0 0" xyz="0 0 0"/>
      <geometry>
        <box size="0.001 0.001 0.001"/>
      </geometry>
    </visual>
  </link>
  <joint name="base_footprint_joint" type="fixed">
    <origin rpy="0 0 0" xyz="0 0 0.093"/>
    <!-- ${wheel_radius} property must be defined inside wheel description -->
    <parent link="base_footprint"/>
    <child link="base_link"/>
  </joint>
  <!-- BASE_LINK -->
  <link name="base_link">
    <inertial>
      <mass value="1000"/>
      <origin xyz="0 0 0"/>
      <inertia ixx="16.6666666667" ixy="0" ixz="0" iyy="44.1666666667" iyz="0" izz="54.1666666667"/>
    </inertial>
    <visual>
      <origin rpy="0 0 0" xyz="0 0 0"/>
      <!--<xacro:if value="${hq}">-->
      <geometry>
        <mesh filename="package://vulcano_base_description/meshes/bases/cabinet.stl"/>
      </geometry>
      <!--</xacro:if>-->
      <material name="darkgrey">
        <color rgba="0.1 0.1 0.1 1"/>
      </material>
    </visual>
    <collision>
      <origin rpy="0 0 0 " xyz="0 0 0"/>
      <geometry>
        <mesh filename="package://vulcano_base_description/meshes/bases/cabinet.stl"/>
      </geometry>
    </collision>
  </link>
  <!--MOTOR WHEEL -->
  <joint name="front_right_wheel_steer_joint" type="revolute">
    <parent link="base_link"/>
    <child link="front_right_wheel_steer_link"/>
    <origin rpy="0 0 0" xyz="0.6165 -0.285 0.0"/>
    <axis rpy="0 0 0" xyz="0 0 1"/>
    <limit effort="100.0" lower="-2.9" upper="2.9" velocity="2"/>
    <dynamics damping="2000.0" friction="1000.0"/>
  </joint>
  <transmission name="front_right_wheel_steer_trans">
    <type>transmission_interface/SimpleTransmission</type>
    <joint name="front_right_wheel_steer_joint">
      <hardwareInterface>PositionJointInterface</hardwareInterface>
    </joint>
    <actuator name="front_right_wheel_steer_motor">
      <hardwareInterface>PositionActuatorInterface</hardwareInterface>
      <mechanicalReduction>1.0</mechanicalReduction>
    </actuator>
  </transmission>
  <link name="front_right_wheel_steer_link">
    <visual>
      <origin rpy="0 0 0" xyz="0 0 0"/>
      <geometry>
        <mesh filename="package://vulcano_base_description/meshes/wheels/hub.stl"/>
      </geometry>
    </visual>
    <collision>
      <origin rpy="0 0 0" xyz="0 0 0"/>
      <geometry>
        <mesh filename="package://vulcano_base_description/meshes/wheels/hub.stl"/>
      </geometry>
    </collision>
    <inertial>
      <mass value="5.0"/>
      <origin xyz="0 0 0"/>
      <inertia ixx="0.02810375" ixy="0" ixz="0" iyy="0.02810375" iyz="0" izz="0.049"/>
      <!-- TODO: check inertia -->
    </inertial>
  </link>
  <!--WHEEL TIRE -->
  <joint name="front_right_wheel_traction_joint" type="continuous">
    <parent link="front_right_wheel_steer_link"/>
    <child link="front_right_wheel_traction_link"/>
    <origin rpy="0 0 3.14159265359" xyz="0 0.0035 0"/>
    <axis rpy="0 0 0" xyz="0 1 0"/>
    <limit effort="1000.0" velocity="6.28"/>
    <dynamics damping="1000.0" friction="1000.0"/>
  </joint>
  <transmission name="front_right_wheel_traction">
    <type>transmission_interface/SimpleTransmission</type>
    <joint name="front_right_wheel_traction_joint">
      <hardwareInterface>VelocityJointInterface</hardwareInterface>
    </joint>
    <actuator name="front_right_wheel_traction_motor">
      <hardwareInterface>VelocityActuatorInterface</hardwareInterface>
      <mechanicalReduction>1.0</mechanicalReduction>
    </actuator>
  </transmission>
  <link name="front_right_wheel_traction_link">
    <visual>
      <origin rpy="0 0 0" xyz="0 0 0"/>
      <geometry>
        <mesh filename="package://vulcano_base_description/meshes/wheels/rubber_band.stl"/>
      </geometry>
    </visual>
    <collision>
      <origin rpy="0 0 0" xyz="0 0 0"/>
      <geometry>
        <mesh filename="package://vulcano_base_description/meshes/wheels/rubber_band.stl"/>
      </geometry>
    </collision>
    <inertial>
      <mass value="5.0"/>
      <origin xyz="0 0 0"/>
      <inertia ixx="0.0189779166667" ixy="0" ixz="0" iyy="0.0189779166667" iyz="0" izz="0.0216225"/>
    </inertial>
  </link>
  <!--<gazebo reference="${prefix}wheel_tracion_link">-->
  <!--<mu1 value="1.0"/>-->
  <!--<mu2 value="1.0"/>-->
  <!--[><kp value="10000000.0" /><]-->
  <!--[><kd value="1.0" /><]-->
  <!--[><fdir1 value="1 0 0"/><]-->
  <!--[><turnGravityOff>false</turnGravityOff><]-->
  <!--</gazebo>-->
  <!-- gazebo reference="${prefix}motor_wheel_link">
        <mu1 value="1.0"/>
        <mu2 value="1.0"/>
        <kp value="10000000.0" />
        <kd value="1.0" />
        <fdir1 value="1 0 0"/>
        <turnGravityOff>false</turnGravityOff>
   </gazebo -->
  <!--MOTOR WHEEL -->
  <joint name="front_left_wheel_steer_joint" type="revolute">
    <parent link="base_link"/>
    <child link="front_left_wheel_steer_link"/>
    <origin rpy="0 0 3.1415926518" xyz="0.6165 0.285 0.0"/>
    <axis rpy="0 0 0" xyz="0 0 1"/>
    <limit effort="100.0" lower="-2.9" upper="2.9" velocity="2"/>
    <dynamics damping="2000.0" friction="1000.0"/>
  </joint>
  <transmission name="front_left_wheel_steer_trans">
    <type>transmission_interface/SimpleTransmission</type>
    <joint name="front_left_wheel_steer_joint">
      <hardwareInterface>PositionJointInterface</hardwareInterface>
    </joint>
    <actuator name="front_left_wheel_steer_motor">
      <hardwareInterface>PositionActuatorInterface</hardwareInterface>
      <mechanicalReduction>1.0</mechanicalReduction>
    </actuator>
  </transmission>
  <link name="front_left_wheel_steer_link">
    <visual>
      <origin rpy="0 0 0" xyz="0 0 0"/>
      <geometry>
        <mesh filename="package://vulcano_base_description/meshes/wheels/hub.stl"/>
      </geometry>
    </visual>
    <collision>
      <origin rpy="0 0 0" xyz="0 0 0"/>
      <geometry>
        <mesh filename="package://vulcano_base_description/meshes/wheels/hub.stl"/>
      </geometry>
    </collision>
    <inertial>
      <mass value="5.0"/>
      <origin xyz="0 0 0"/>
      <inertia ixx="0.02810375" ixy="0" ixz="0" iyy="0.02810375" iyz="0" izz="0.049"/>
      <!-- TODO: check inertia -->
    </inertial>
  </link>
  <!--WHEEL TIRE -->
  <joint name="front_left_wheel_traction_joint" type="continuous">
    <parent link="front_left_wheel_steer_link"/>
    <child link="front_left_wheel_traction_link"/>
    <origin rpy="0 0 3.14159265359" xyz="0 0.0035 0"/>
    <axis rpy="0 0 0" xyz="0 1 0"/>
    <limit effort="1000.0" velocity="6.28"/>
    <dynamics damping="1000.0" friction="1000.0"/>
  </joint>
  <transmission name="front_left_wheel_traction">
    <type>transmission_interface/SimpleTransmission</type>
    <joint name="front_left_wheel_traction_joint">
      <hardwareInterface>VelocityJointInterface</hardwareInterface>
    </joint>
    <actuator name="front_left_wheel_traction_motor">
      <hardwareInterface>VelocityActuatorInterface</hardwareInterface>
      <mechanicalReduction>1.0</mechanicalReduction>
    </actuator>
  </transmission>
  <link name="front_left_wheel_traction_link">
    <visual>
      <origin rpy="0 0 0" xyz="0 0 0"/>
      <geometry>
        <mesh filename="package://vulcano_base_description/meshes/wheels/rubber_band.stl"/>
      </geometry>
    </visual>
    <collision>
      <origin rpy="0 0 0" xyz="0 0 0"/>
      <geometry>
        <mesh filename="package://vulcano_base_description/meshes/wheels/rubber_band.stl"/>
      </geometry>
    </collision>
    <inertial>
      <mass value="5.0"/>
      <origin xyz="0 0 0"/>
      <inertia ixx="0.0189779166667" ixy="0" ixz="0" iyy="0.0189779166667" iyz="0" izz="0.0216225"/>
    </inertial>
  </link>
  <!--<gazebo reference="${prefix}wheel_tracion_link">-->
  <!--<mu1 value="1.0"/>-->
  <!--<mu2 value="1.0"/>-->
  <!--[><kp value="10000000.0" /><]-->
  <!--[><kd value="1.0" /><]-->
  <!--[><fdir1 value="1 0 0"/><]-->
  <!--[><turnGravityOff>false</turnGravityOff><]-->
  <!--</gazebo>-->
  <!-- gazebo reference="${prefix}motor_wheel_link">
        <mu1 value="1.0"/>
        <mu2 value="1.0"/>
        <kp value="10000000.0" />
        <kd value="1.0" />
        <fdir1 value="1 0 0"/>
        <turnGravityOff>false</turnGravityOff>
   </gazebo -->
  <!--MOTOR WHEEL -->
  <joint name="back_left_wheel_steer_joint" type="revolute">
    <parent link="base_link"/>
    <child link="back_left_wheel_steer_link"/>
    <origin rpy="0 0 3.1415926518" xyz="-0.6165 0.285 0.0"/>
    <axis rpy="0 0 0" xyz="0 0 1"/>
    <limit effort="100.0" lower="-2.9" upper="2.9" velocity="2"/>
    <dynamics damping="2000.0" friction="1000.0"/>
  </joint>
  <transmission name="back_left_wheel_steer_trans">
    <type>transmission_interface/SimpleTransmission</type>
    <joint name="back_left_wheel_steer_joint">
      <hardwareInterface>PositionJointInterface</hardwareInterface>
    </joint>
    <actuator name="back_left_wheel_steer_motor">
      <hardwareInterface>PositionActuatorInterface</hardwareInterface>
      <mechanicalReduction>1.0</mechanicalReduction>
    </actuator>
  </transmission>
  <link name="back_left_wheel_steer_link">
    <visual>
      <origin rpy="0 0 0" xyz="0 0 0"/>
      <geometry>
        <mesh filename="package://vulcano_base_description/meshes/wheels/hub.stl"/>
      </geometry>
    </visual>
    <collision>
      <origin rpy="0 0 0" xyz="0 0 0"/>
      <geometry>
        <mesh filename="package://vulcano_base_description/meshes/wheels/hub.stl"/>
      </geometry>
    </collision>
    <inertial>
      <mass value="5.0"/>
      <origin xyz="0 0 0"/>
      <inertia ixx="0.02810375" ixy="0" ixz="0" iyy="0.02810375" iyz="0" izz="0.049"/>
      <!-- TODO: check inertia -->
    </inertial>
  </link>
  <!--WHEEL TIRE -->
  <joint name="back_left_wheel_traction_joint" type="continuous">
    <parent link="back_left_wheel_steer_link"/>
    <child link="back_left_wheel_traction_link"/>
    <origin rpy="0 0 3.14159265359" xyz="0 0.0035 0"/>
    <axis rpy="0 0 0" xyz="0 1 0"/>
    <limit effort="1000.0" velocity="6.28"/>
    <dynamics damping="1000.0" friction="1000.0"/>
  </joint>
  <transmission name="back_left_wheel_traction">
    <type>transmission_interface/SimpleTransmission</type>
    <joint name="back_left_wheel_traction_joint">
      <hardwareInterface>VelocityJointInterface</hardwareInterface>
    </joint>
    <actuator name="back_left_wheel_traction_motor">
      <hardwareInterface>VelocityActuatorInterface</hardwareInterface>
      <mechanicalReduction>1.0</mechanicalReduction>
    </actuator>
  </transmission>
  <link name="back_left_wheel_traction_link">
    <visual>
      <origin rpy="0 0 0" xyz="0 0 0"/>
      <geometry>
        <mesh filename="package://vulcano_base_description/meshes/wheels/rubber_band.stl"/>
      </geometry>
    </visual>
    <collision>
      <origin rpy="0 0 0" xyz="0 0 0"/>
      <geometry>
        <mesh filename="package://vulcano_base_description/meshes/wheels/rubber_band.stl"/>
      </geometry>
    </collision>
    <inertial>
      <mass value="5.0"/>
      <origin xyz="0 0 0"/>
      <inertia ixx="0.0189779166667" ixy="0" ixz="0" iyy="0.0189779166667" iyz="0" izz="0.0216225"/>
    </inertial>
  </link>
  <!--<gazebo reference="${prefix}wheel_tracion_link">-->
  <!--<mu1 value="1.0"/>-->
  <!--<mu2 value="1.0"/>-->
  <!--[><kp value="10000000.0" /><]-->
  <!--[><kd value="1.0" /><]-->
  <!--[><fdir1 value="1 0 0"/><]-->
  <!--[><turnGravityOff>false</turnGravityOff><]-->
  <!--</gazebo>-->
  <!-- gazebo reference="${prefix}motor_wheel_link">
        <mu1 value="1.0"/>
        <mu2 value="1.0"/>
        <kp value="10000000.0" />
        <kd value="1.0" />
        <fdir1 value="1 0 0"/>
        <turnGravityOff>false</turnGravityOff>
   </gazebo -->
  <!--MOTOR WHEEL -->
  <joint name="back_right_wheel_steer_joint" type="revolute">
    <parent link="base_link"/>
    <child link="back_right_wheel_steer_link"/>
    <origin rpy="0 0 0" xyz="-0.6165 -0.285 0.0"/>
    <axis rpy="0 0 0" xyz="0 0 1"/>
    <limit effort="100.0" lower="-2.9" upper="2.9" velocity="2"/>
    <dynamics damping="2000.0" friction="1000.0"/>
  </joint>
  <transmission name="back_right_wheel_steer_trans">
    <type>transmission_interface/SimpleTransmission</type>
    <joint name="back_right_wheel_steer_joint">
      <hardwareInterface>PositionJointInterface</hardwareInterface>
    </joint>
    <actuator name="back_right_wheel_steer_motor">
      <hardwareInterface>PositionActuatorInterface</hardwareInterface>
      <mechanicalReduction>1.0</mechanicalReduction>
    </actuator>
  </transmission>
  <link name="back_right_wheel_steer_link">
    <visual>
      <origin rpy="0 0 0" xyz="0 0 0"/>
      <geometry>
        <mesh filename="package://vulcano_base_description/meshes/wheels/hub.stl"/>
      </geometry>
    </visual>
    <collision>
      <origin rpy="0 0 0" xyz="0 0 0"/>
      <geometry>
        <mesh filename="package://vulcano_base_description/meshes/wheels/hub.stl"/>
      </geometry>
    </collision>
    <inertial>
      <mass value="5.0"/>
      <origin xyz="0 0 0"/>
      <inertia ixx="0.02810375" ixy="0" ixz="0" iyy="0.02810375" iyz="0" izz="0.049"/>
      <!-- TODO: check inertia -->
    </inertial>
  </link>
  <!--WHEEL TIRE -->
  <joint name="back_right_wheel_traction_joint" type="continuous">
    <parent link="back_right_wheel_steer_link"/>
    <child link="back_right_wheel_traction_link"/>
    <origin rpy="0 0 3.14159265359" xyz="0 0.0035 0"/>
    <axis rpy="0 0 0" xyz="0 1 0"/>
    <limit effort="1000.0" velocity="6.28"/>
    <dynamics damping="1000.0" friction="1000.0"/>
  </joint>
  <transmission name="back_right_wheel_traction">
    <type>transmission_interface/SimpleTransmission</type>
    <joint name="back_right_wheel_traction_joint">
      <hardwareInterface>VelocityJointInterface</hardwareInterface>
    </joint>
    <actuator name="back_right_wheel_traction_motor">
      <hardwareInterface>VelocityActuatorInterface</hardwareInterface>
      <mechanicalReduction>1.0</mechanicalReduction>
    </actuator>
  </transmission>
  <link name="back_right_wheel_traction_link">
    <visual>
      <origin rpy="0 0 0" xyz="0 0 0"/>
      <geometry>
        <mesh filename="package://vulcano_base_description/meshes/wheels/rubber_band.stl"/>
      </geometry>
    </visual>
    <collision>
      <origin rpy="0 0 0" xyz="0 0 0"/>
      <geometry>
        <mesh filename="package://vulcano_base_description/meshes/wheels/rubber_band.stl"/>
      </geometry>
    </collision>
    <inertial>
      <mass value="5.0"/>
      <origin xyz="0 0 0"/>
      <inertia ixx="0.0189779166667" ixy="0" ixz="0" iyy="0.0189779166667" iyz="0" izz="0.0216225"/>
    </inertial>
  </link>
  <!--<gazebo reference="${prefix}wheel_tracion_link">-->
  <!--<mu1 value="1.0"/>-->
  <!--<mu2 value="1.0"/>-->
  <!--[><kp value="10000000.0" /><]-->
  <!--[><kd value="1.0" /><]-->
  <!--[><fdir1 value="1 0 0"/><]-->
  <!--[><turnGravityOff>false</turnGravityOff><]-->
  <!--</gazebo>-->
  <!-- gazebo reference="${prefix}motor_wheel_link">
        <mu1 value="1.0"/>
        <mu2 value="1.0"/>
        <kp value="10000000.0" />
        <kd value="1.0" />
        <fdir1 value="1 0 0"/>
        <turnGravityOff>false</turnGravityOff>
   </gazebo -->
  <joint name="imu_joint" type="fixed">
    <axis xyz="1 0 0"/>
    <!--origin xyz="0 0 0.2825"/-->
    <origin rpy="0 0 0" xyz="-0.40 0.06 0.75"/>
    <parent link="base_link"/>
    <child link="imu_link"/>
  </joint>
  <link name="imu_link">
    <inertial>
      <mass value="0.001"/>
      <origin rpy="0 0 0" xyz="0 0 0"/>
      <inertia ixx="0.0001" ixy="0" ixz="0" iyy="0.000001" iyz="0" izz="0.0001"/>
    </inertial>
    <visual>
      <origin rpy="0 0 0" xyz="0 0 0"/>
      <geometry>
        <box size="0.001 0.001 0.001"/>
      </geometry>
    </visual>
    <collision>
      <origin rpy="0 0 0" xyz="0 0 0"/>
      <geometry>
        <box size=".001 .001 .001"/>
      </geometry>
    </collision>
  </link>
  <gazebo>
    <plugin filename="libgazebo_ros_imu.so" name="imu_controller">
      <topicName>imu/data</topicName>
      <serviceName>imu/service</serviceName>
      <bodyName>imu_link</bodyName>
      <updateRateHZ>50.0</updateRateHZ>
      <gaussianNoise>0.005</gaussianNoise>
    </plugin>
  </gazebo>
  <joint name="front_left_laser_base_joint" type="fixed">
    <origin rpy="3.1415926518 0 0.78539816295" xyz="0.75631 0.34581 0.30676"/>
    <parent link="base_link"/>
    <child link="front_left_laser_base_link"/>
  </joint>
  <link name="front_left_laser_base_link">
    <collision>
      <origin rpy="0 0 0" xyz="0 0 0"/>
      <geometry>
        <!--<box size="0.106 0.094 0.152"/>-->
        <!--<cylinder radius="0.058" length="0.152"/>-->
        <mesh filename="package://robotnik_sensors/meshes/sick_s300.dae"/>
      </geometry>
    </collision>
    <visual>
      <origin rpy="0 0 0" xyz="0 0 0"/>
      <geometry>
        <mesh filename="package://robotnik_sensors/meshes/sick_s300.dae"/>
      </geometry>
    </visual>
    <inertial>
      <mass value="1e-5"/>
      <origin rpy="0 0 0" xyz="0 0 0"/>
      <inertia ixx="1e-6" ixy="0" ixz="0" iyy="1e-6" iyz="0" izz="1e-6"/>
    </inertial>
  </link>
  <joint name="front_left_laser_joint" type="fixed">
    <parent link="front_left_laser_base_link"/>
    <child link="front_left_laser_link"/>
    <origin rpy="0 0 0" xyz="0.0 0 0.116"/>
  </joint>
  <link name="front_left_laser_link"/>
  <gazebo reference="front_left_laser_link">
    <sensor name="front_left_laser_sensor" type="ray">
      <pose>0 0 0 0 0 0</pose>
      <visualize>false</visualize>
      <update_rate>12.5</update_rate>
      <ray>
        <scan>
          <horizontal>
            <samples>541</samples>
            <resolution>1</resolution>
            <min_angle>-2.3562</min_angle>
            <max_angle>2.3562</max_angle>
          </horizontal>
        </scan>
        <range>
          <min>0.10</min>
          <max>30.0</max>
          <resolution>0.03</resolution>
        </range>
        <noise>
          <type>gaussian</type>
          <mean>0.0</mean>
          <stddev>0.03</stddev>
        </noise>
      </ray>
      <plugin filename="libgazebo_ros_laser.so" name="front_left_laser_controller">
        <topicName>front_laser/scan</topicName>
        <frameName>/front_left_laser_link</frameName>
        <!-- if not global (leading /) sets the current namespace as a prefix (/ns/name_laser_link) -->
      </plugin>
    </sensor>
  </gazebo>
  <joint name="back_right_laser_base_joint" type="fixed">
    <origin rpy="3.1415926518 0 3.92699081475" xyz="-0.75631 -0.34581 0.30676"/>
    <parent link="base_link"/>
    <child link="back_right_laser_base_link"/>
  </joint>
  <link name="back_right_laser_base_link">
    <collision>
      <origin rpy="0 0 0" xyz="0 0 0"/>
      <geometry>
        <!--<box size="0.106 0.094 0.152"/>-->
        <!--<cylinder radius="0.058" length="0.152"/>-->
        <mesh filename="package://robotnik_sensors/meshes/sick_s300.dae"/>
      </geometry>
    </collision>
    <visual>
      <origin rpy="0 0 0" xyz="0 0 0"/>
      <geometry>
        <mesh filename="package://robotnik_sensors/meshes/sick_s300.dae"/>
      </geometry>
    </visual>
    <inertial>
      <mass value="1e-5"/>
      <origin rpy="0 0 0" xyz="0 0 0"/>
      <inertia ixx="1e-6" ixy="0" ixz="0" iyy="1e-6" iyz="0" izz="1e-6"/>
    </inertial>
  </link>
  <joint name="back_right_laser_joint" type="fixed">
    <parent link="back_right_laser_base_link"/>
    <child link="back_right_laser_link"/>
    <origin rpy="0 0 0" xyz="0.0 0 0.116"/>
  </joint>
  <link name="back_right_laser_link"/>
  <gazebo reference="back_right_laser_link">
    <sensor name="back_right_laser_sensor" type="ray">
      <pose>0 0 0 0 0 0</pose>
      <visualize>false</visualize>
      <update_rate>12.5</update_rate>
      <ray>
        <scan>
          <horizontal>
            <samples>541</samples>
            <resolution>1</resolution>
            <min_angle>-2.3562</min_angle>
            <max_angle>2.3562</max_angle>
          </horizontal>
        </scan>
        <range>
          <min>0.10</min>
          <max>30.0</max>
          <resolution>0.03</resolution>
        </range>
        <noise>
          <type>gaussian</type>
          <mean>0.0</mean>
          <stddev>0.03</stddev>
        </noise>
      </ray>
      <plugin filename="libgazebo_ros_laser.so" name="back_right_laser_controller">
        <topicName>front_laser/scan</topicName>
        <frameName>/back_right_laser_link</frameName>
        <!-- if not global (leading /) sets the current namespace as a prefix (/ns/name_laser_link) -->
      </plugin>
    </sensor>
  </gazebo>
  <!-- Fix torso to base -->
  <joint name="base_torso_joint" type="fixed">
    <origin rpy="0.0 0.0 0.0" xyz="0.5607 0.0 0.4845"/>
    <parent link="base_link"/>
    <child link="torso_base_link"/>
    <axis xyz="0 0 0"/>
  </joint>
  <!-- TODO: check hq variable -->
  <link name="torso_base_link">
    <inertial>
      <origin rpy="0 0 0 " xyz="0 0 0"/>
      <mass value="5"/>
      <!-- TODO: check masses -->
      <inertia ixx="1.0" ixy="0.0" ixz="0.0" iyy="1.0" iyz="0.0" izz="1.0"/>
    </inertial>
  </link>
  <joint name="torso_guidance_base_joint" type="fixed">
    <origin rpy="0 0 0" xyz="0.0 0.0 0.0"/>
    <parent link="torso_base_link"/>
    <child link="torso_guidance_base_link"/>
    <axis xyz="0 0 1"/>
  </joint>
  <link name="torso_guidance_base_link">
    <inertial>
      <mass value="128"/>
      <origin xyz="0 0 0"/>
      <inertia ixx="29.12" ixy="0" ixz="0" iyy="29.12" iyz="0" izz="10.24"/>
      <!-- TODO: check inertia -->
    </inertial>
  </link>
  <joint name="torso_guidance_revolution_joint" type="revolute">
    <origin rpy="0 0 3.14159265359" xyz="0 0 0"/>
    <parent link="torso_guidance_base_link"/>
    <child link="torso_guidance_revolution_link"/>
    <axis xyz="0 0 1"/>
    <limit effort="100" lower="-2.4434609514" upper="3.8397243522" velocity="0.4"/>
    <dynamics damping="1000" friction="1000"/>
  </joint>
  <transmission name="torso_guidance_revolution_trans">
    <type>transmission_interface/SimpleTransmission</type>
    <joint name="torso_guidance_revolution_joint">
      <hardwareInterface>PositionJointInterface</hardwareInterface>
    </joint>
    <actuator name="torso_guidance_revolution_motor">
      <mechanicalReduction>1</mechanicalReduction>
    </actuator>
  </transmission>
  <link name="torso_guidance_revolution_link">
    <visual>
      <origin rpy="0 0 0" xyz="0 0 0"/>
      <geometry>
        <mesh filename="package://vulcano_torso_description/meshes/guidance/guidance.stl"/>
      </geometry>
      <material name="darkgrey">
        <color rgba="0.1 0.1 0.1 1"/>
      </material>
    </visual>
    <collision>
      <origin rpy="0 0 0" xyz="0 0 0"/>
      <geometry>
        <mesh filename="package://vulcano_torso_description/meshes/guidance/guidance.stl"/>
      </geometry>
    </collision>
    <inertial>
      <mass value="128"/>
      <origin xyz="0 0 0"/>
      <inertia ixx="29.12" ixy="0" ixz="0" iyy="29.12" iyz="0" izz="10.24"/>
      <!-- TODO: check inertia -->
    </inertial>
  </link>
  <joint name="torso_guidance_elevation_joint" type="prismatic">
    <origin rpy="0 0 0" xyz="-0.1687 0 0.720"/>
    <parent link="torso_guidance_revolution_link"/>
    <child link="torso_guidance_elevation_link"/>
    <axis xyz="0 0 1"/>
    <limit effort="100" lower="0.0" upper="0.6" velocity="0.08"/>
    <dynamics damping="10000" friction="100000"/>
  </joint>
  <transmission name="torso_guidance_elevation_trans">
    <type>transmission_interface/SimpleTransmission</type>
    <joint name="torso_guidance_elevation_joint">
      <hardwareInterface>PositionJointInterface</hardwareInterface>
    </joint>
    <actuator name="torso_guidance_elevation_motor">
      <mechanicalReduction>1</mechanicalReduction>
    </actuator>
  </transmission>
  <link name="torso_guidance_elevation_link">
    <visual>
      <origin rpy="0 0 0" xyz="0 0 0"/>
      <geometry>
        <mesh filename="package://vulcano_torso_description/meshes/guidance/slide.stl"/>
      </geometry>
      <material name="darkgrey">
        <color rgba="0.1 0.1 0.1 1"/>
      </material>
    </visual>
    <collision>
      <origin rpy="0 0 0" xyz="0 0 0"/>
      <geometry>
        <mesh filename="package://vulcano_torso_description/meshes/guidance/slide.stl"/>
      </geometry>
    </collision>
    <inertial>
      <origin rpy="0 0 0" xyz="0.05 0.001 0.432"/>
      <mass value="41"/>
      <inertia ixx="1.881" ixy="-0.004" ixz="0.084" iyy="1.122" iyz="-0.008" izz="1.295"/>
    </inertial>
  </link>
  <joint name="torso_guidance_pantilt_joint" type="fixed">
    <origin rpy="0 0 3.1415926518" xyz="-0.191 0.0 1.178"/>
    <parent link="torso_guidance_revolution_link"/>
    <child link="torso_guidance_pantilt_link"/>
    <axis xyz="0 0 1"/>
  </joint>
  <link name="torso_guidance_pantilt_link">
    <inertial>
      <origin rpy="0 0 0 " xyz="0 0 0"/>
      <mass value="5"/>
      <!-- TODO: check masses -->
      <inertia ixx="1.0" ixy="0.0" ixz="0.0" iyy="1.0" iyz="0.0" izz="1.0"/>
    </inertial>
  </link>
  <!-- PAN TILT BASE -->
  <joint name="torso_pantilt_base_joint" type="fixed">
    <origin rpy="0 0 0" xyz="0.0 0.0 0.0"/>
    <parent link="torso_guidance_pantilt_link"/>
    <!--<parent link="${prefix}torso_base_link"/>-->
    <child link="torso_pantilt_base_link"/>
    <axis xyz="0 0 1"/>
  </joint>
  <link name="torso_pantilt_base_link">
    <visual>
      <origin rpy="0 0 0" xyz="0 0 0"/>
      <geometry>
        <mesh filename="package://vulcano_torso_description/meshes/pantilt/base.stl"/>
      </geometry>
      <material name="lightgrey">
        <color rgba="0.3 0.3 0.3 1"/>
      </material>
    </visual>
    <collision>
      <origin rpy="0 0 0" xyz="0 0 0"/>
      <geometry>
        <mesh filename="package://vulcano_torso_description/meshes/pantilt/base.stl"/>
      </geometry>
    </collision>
    <inertial>
      <origin rpy="0 0 0" xyz="0 0 0"/>
      <mass value="5"/>
      <inertia ixx="1.0" ixy="0.0" ixz="0.0" iyy="1.0" iyz="0.0" izz="1.0"/>
    </inertial>
  </link>
  <!-- PAN JOINT/LINK -->
  <joint name="torso_pantilt_pan_base_joint" type="fixed">
    <origin rpy="0 0 0" xyz="0.0 0.0 0.0"/>
    <parent link="torso_pantilt_base_link"/>
    <child link="torso_pantilt_pan_base_link"/>
    <axis xyz="0 0 1"/>
  </joint>
  <link name="torso_pantilt_pan_base_link">
    <visual>
      <origin rpy="0 0 0" xyz="0 0 0"/>
      <geometry>
        <mesh filename="package://vulcano_torso_description/meshes/pantilt/dynamixel_l42.stl"/>
      </geometry>
      <material name="lightgrey">
        <color rgba="0.3 0.3 0.3 1"/>
      </material>
    </visual>
    <collision>
      <origin rpy="0 0 0" xyz="0 0 0"/>
      <geometry>
        <mesh filename="package://vulcano_torso_description/meshes/pantilt/dynamixel_l42.stl"/>
      </geometry>
    </collision>
    <inertial>
      <origin rpy="0 0 0" xyz="0 0 0"/>
      <mass value="5"/>
      <inertia ixx="1.0" ixy="0.0" ixz="0.0" iyy="1.0" iyz="0.0" izz="1.0"/>
    </inertial>
  </link>
  <joint name="torso_pantilt_pan_joint" type="revolute">
    <origin rpy="0 0 0" xyz="0.0 0.0 0.111"/>
    <parent link="torso_pantilt_pan_base_link"/>
    <child link="torso_pantilt_pan_link"/>
    <axis xyz="0 0 1"/>
    <limit effort="100" lower="-0.95" upper="0.95" velocity="100"/>
    <dynamics damping="1000" friction="1000"/>
  </joint>
  <transmission name="torso_pantilt_pan_trans">
    <type>transmission_interface/SimpleTransmission</type>
    <joint name="torso_pantilt_pan_joint">
      <hardwareInterface>PositionJointInterface</hardwareInterface>
      <!-- TODO: PositionJointInterface? EffortJointInterface? -->
    </joint>
    <actuator name="torso_pantilt_pan_motor">
      <mechanicalReduction>1</mechanicalReduction>
      <hardwareInterface>PositionJointInterface</hardwareInterface>
    </actuator>
  </transmission>
  <link name="torso_pantilt_pan_link">
    <visual>
      <origin rpy="0 0 0" xyz="0 0 0"/>
      <geometry>
        <mesh filename="package://vulcano_torso_description/meshes/pantilt/pan.stl"/>
      </geometry>
      <material name="lightgrey">
        <color rgba="0.3 0.3 0.3 1"/>
      </material>
    </visual>
    <collision>
      <origin rpy="0 0 0" xyz="0 0 0"/>
      <geometry>
        <mesh filename="package://vulcano_torso_description/meshes/pantilt/pan.stl"/>
      </geometry>
    </collision>
    <inertial>
      <origin rpy="0 0 0" xyz="0 0 0"/>
      <mass value="5"/>
      <inertia ixx="1.0" ixy="0.0" ixz="0.0" iyy="1.0" iyz="0.0" izz="1.0"/>
    </inertial>
  </link>
  <!-- TILT JOINT/LINK -->
  <joint name="torso_pantilt_tilt_joint" type="revolute">
    <origin rpy="-1.57 0 0" xyz="0.0 -0.027 0.0"/>
    <parent link="torso_pantilt_pan_link"/>
    <child link="torso_pantilt_tilt_base_link"/>
    <axis xyz="0 0 1"/>
    <limit effort="100" lower="-1.26" upper="1.26" velocity="100"/>
    <dynamics damping="1000" friction="1000"/>
  </joint>
  <transmission name="torso_pantilt_tilt_trans">
    <type>transmission_interface/SimpleTransmission</type>
    <joint name="torso_pantilt_tilt_joint">
      <!--<hardwareInterface>EffortJointInterface</hardwareInterface>-->
      <hardwareInterface>PositionJointInterface</hardwareInterface>
      <!-- TODO: PositionJointInterface? EffortJointInterface? -->
    </joint>
    <actuator name="torso_pantilt_tilt_motor">
      <mechanicalReduction>1</mechanicalReduction>
      <hardwareInterface>PositionJointInterface</hardwareInterface>
    </actuator>
  </transmission>
  <link name="torso_pantilt_tilt_base_link">
    <visual>
      <origin rpy="0 0 0" xyz="0 0 0"/>
      <geometry>
        <mesh filename="package://vulcano_torso_description/meshes/pantilt/dynamixel_l42.stl"/>
      </geometry>
      <material name="lightgrey">
        <color rgba="0.3 0.3 0.3 1"/>
      </material>
    </visual>
    <collision>
      <origin rpy="0 0 0" xyz="0 0 0"/>
      <geometry>
        <mesh filename="package://vulcano_torso_description/meshes/pantilt/dynamixel_l42.stl"/>
      </geometry>
    </collision>
    <inertial>
      <origin rpy="0 0 0" xyz="0 0 0"/>
      <mass value="5"/>
      <inertia ixx="1.0" ixy="0.0" ixz="0.0" iyy="1.0" iyz="0.0" izz="1.0"/>
    </inertial>
  </link>
  <joint name="torso_pantilt_tilt_support_joint" type="fixed">
    <origin rpy="1.57 0 0" xyz="0.0 0.0 0.0"/>
    <parent link="torso_pantilt_tilt_base_link"/>
    <child link="torso_pantilt_tilt_support_link"/>
    <axis xyz="0 0 1"/>
  </joint>
  <link name="torso_pantilt_tilt_support_link">
    <visual>
      <origin rpy="0 0 0" xyz="0 0 0"/>
      <geometry>
        <mesh filename="package://vulcano_torso_description/meshes/pantilt/tilt_support.stl"/>
      </geometry>
      <material name="lightgrey">
        <color rgba="0.3 0.3 0.3 1"/>
      </material>
    </visual>
    <collision>
      <origin rpy="0 0 0" xyz="0 0 0"/>
      <geometry>
        <mesh filename="package://vulcano_torso_description/meshes/pantilt/tilt_support.stl"/>
      </geometry>
    </collision>
    <inertial>
      <origin rpy="0 0 0" xyz="0 0 0"/>
      <mass value="5"/>
      <inertia ixx="1.0" ixy="0.0" ixz="0.0" iyy="1.0" iyz="0.0" izz="1.0"/>
    </inertial>
  </link>
  <joint name="torso_pantilt_tilt_fixed_joint" type="fixed">
    <!--<origin xyz="0.0 0.027 0.027" rpy="0 0 0"/>-->
    <origin rpy="1.57 0 0" xyz="0.0 -0.027 0.027"/>
    <parent link="torso_pantilt_tilt_base_link"/>
    <child link="torso_pantilt_tilt_link"/>
  </joint>
  <link name="torso_pantilt_tilt_link">
    <visual>
      <origin rpy="0 0 0" xyz="0 0 0"/>
      <geometry>
        <mesh filename="package://vulcano_torso_description/meshes/pantilt/tilt.stl"/>
      </geometry>
      <material name="lightgrey">
        <color rgba="0.3 0.3 0.3 1"/>
      </material>
    </visual>
    <collision>
      <origin rpy="0 0 0" xyz="0 0 0"/>
      <geometry>
        <mesh filename="package://vulcano_torso_description/meshes/pantilt/tilt.stl"/>
      </geometry>
    </collision>
    <inertial>
      <origin rpy="0 0 0" xyz="0 0 0"/>
      <mass value="5"/>
      <inertia ixx="1.0" ixy="0.0" ixz="0.0" iyy="1.0" iyz="0.0" izz="1.0"/>
    </inertial>
  </link>
  <joint name="torso_pantilt_joint" type="fixed">
    <origin rpy="0 0 0" xyz="0.0 0.0 0.003"/>
    <parent link="torso_pantilt_tilt_link"/>
    <child link="torso_pantilt_link"/>
  </joint>
  <link name="torso_pantilt_link">
    <visual>
      <origin rpy="0 0 0" xyz="0 0 0"/>
      <geometry>
        <mesh filename="package://vulcano_torso_description/meshes/pantilt/pantilt.stl"/>
      </geometry>
      <material name="lightgrey">
        <color rgba="0.3 0.3 0.3 1"/>
      </material>
    </visual>
    <collision>
      <origin rpy="0 0 0" xyz="0 0 0"/>
      <geometry>
        <mesh filename="package://vulcano_torso_description/meshes/pantilt/pantilt.stl"/>
      </geometry>
    </collision>
    <inertial>
      <origin rpy="0 0 0" xyz="0 0 0"/>
      <mass value="5"/>
      <inertia ixx="1.0" ixy="0.0" ixz="0.0" iyy="1.0" iyz="0.0" izz="1.0"/>
    </inertial>
  </link>
  <joint name="torso_effi_joint" type="fixed">
    <origin rpy="0 0 0" xyz="-0.0369 0 0.030"/>
    <parent link="torso_pantilt_link"/>
    <child link="torso_effi_link"/>
  </joint>
  <link name="torso_effi_link">
    <visual>
      <origin rpy="0 0 0" xyz="0 0 0"/>
      <geometry>
        <mesh filename="package://vulcano_torso_description/meshes/pantilt/effi.stl"/>
      </geometry>
      <material name="lightgrey">
        <color rgba="0.3 0.3 0.3 1"/>
      </material>
    </visual>
    <collision>
      <origin rpy="0 0 0" xyz="0 0 0"/>
      <geometry>
        <mesh filename="package://vulcano_torso_description/meshes/pantilt/effi.stl"/>
      </geometry>
    </collision>
    <inertial>
      <origin rpy="0 0 0" xyz="0 0 0"/>
      <mass value="5"/>
      <inertia ixx="1.0" ixy="0.0" ixz="0.0" iyy="1.0" iyz="0.0" izz="1.0"/>
    </inertial>
  </link>
  <!-- camera body, with origin at bottom screw mount -->
  <joint name="torso_realsense_camera_joint" type="fixed">
    <origin rpy="0 0 0" xyz="0.01255 0 0.066"/>
    <parent link="torso_pantilt_link"/>
    <child link="torso_realsense_camera_link"/>
  </joint>
  <link name="torso_realsense_camera_link">
    <visual>
      <!-- origin xyz="0 ${-r430_cam_mount_from_center_offset} ${r430_cam_height/2}" rpy="${M_PI/2} 0 ${M_PI/2}"/ -->
      <origin rpy="0 0 0" xyz="0 -0.0 0"/>
      <geometry>
        <!-- box size="${r430_cam_width} ${r430_cam_height} ${r430_cam_depth}"/ -->
        <mesh filename="package://robotnik_sensors/meshes/intel_realsense_depth_camera_d435.dae"/>
      </geometry>
      <material name="aluminum"/>
    </visual>
    <collision>
      <origin rpy="0 0 0" xyz="-0.0125 0.0 0.0"/>
      <geometry>
        <box size="0.025 0.1 0.025"/>
      </geometry>
    </collision>
    <inertial>
      <!-- The following are not reliable values, and should not be used for modeling -->
      <mass value="0.564"/>
      <origin xyz="0 0 0"/>
      <inertia ixx="0.003881243" ixy="0.0" ixz="0.0" iyy="0.000498940" iyz="0.0" izz="0.003879257"/>
    </inertial>
  </link>
  <!-- camera depth joints and links -->
  <joint name="torso_realsense_camera_depth_joint" type="fixed">
    <origin rpy="0 0 0" xyz="0.0 -0.0115 0.0"/>
    <parent link="torso_realsense_camera_link"/>
    <child link="torso_realsense_camera_depth_frame"/>
  </joint>
  <link name="torso_realsense_camera_depth_frame"/>
  <joint name="torso_realsense_camera_depth_optical_joint" type="fixed">
    <origin rpy="-1.57079632679 0 -1.57079632679" xyz="0 0 0"/>
    <parent link="torso_realsense_camera_depth_frame"/>
    <child link="torso_realsense_camera_depth_optical_frame"/>
  </joint>
  <link name="torso_realsense_camera_depth_optical_frame"/>
  <!-- camera left IR joints and links -->
  <joint name="torso_realsense_camera_left_ir_joint" type="fixed">
    <origin rpy="0 0 0" xyz="0 -0.021 0"/>
    <parent link="torso_realsense_camera_depth_frame"/>
    <child link="torso_realsense_camera_left_ir_frame"/>
  </joint>
  <link name="torso_realsense_camera_left_ir_frame"/>
  <joint name="torso_realsense_camera_left_ir_optical_joint" type="fixed">
    <origin rpy="-1.57079632679 0 -1.57079632679" xyz="0 0 0"/>
    <parent link="torso_realsense_camera_left_ir_frame"/>
    <child link="torso_realsense_camera_left_ir_optical_frame"/>
  </joint>
  <link name="torso_realsense_camera_left_ir_optical_frame"/>
  <!-- camera right IR joints and links -->
  <joint name="torso_realsense_camera_right_ir_joint" type="fixed">
    <origin rpy="0 0 0" xyz="0 0.029 0"/>
    <parent link="torso_realsense_camera_depth_frame"/>
    <child link="torso_realsense_camera_right_ir_frame"/>
  </joint>
  <link name="torso_realsense_camera_right_ir_frame"/>
  <joint name="torso_realsense_camera_right_ir_optical_joint" type="fixed">
    <origin rpy="-1.57079632679 0 -1.57079632679" xyz="0 0 0"/>
    <parent link="torso_realsense_camera_right_ir_frame"/>
    <child link="torso_realsense_camera_right_ir_optical_frame"/>
  </joint>
  <link name="torso_realsense_camera_right_ir_optical_frame"/>
  <!-- camera fisheye joints and links -->
  <joint name="torso_realsense_camera_fisheye_joint" type="fixed">
    <origin rpy="0 0 0" xyz="0 0.044 0"/>
    <parent link="torso_realsense_camera_depth_frame"/>
    <child link="torso_realsense_camera_fisheye_frame"/>
  </joint>
  <link name="torso_realsense_camera_fisheye_frame"/>
  <joint name="torso_realsense_camera_fisheye_optical_joint" type="fixed">
    <origin rpy="-1.57079632679 0 -1.57079632679" xyz="0 0 0"/>
    <parent link="torso_realsense_camera_fisheye_frame"/>
    <child link="torso_realsense_camera_fisheye_optical_frame"/>
  </joint>
  <link name="torso_realsense_camera_fisheye_optical_frame"/>
  <!-- gazebo reference="${prefix}_rgb_base_link" -->
  <gazebo reference="torso_realsense_camera_link">
    <sensor name="torso_realsense_depth_sensor" type="depth">
      <always_on>true</always_on>
      <update_rate>15.0</update_rate>
      <camera>
        <horizontal_fov>1.59174027782</horizontal_fov>
        <image>
          <format>R8G8B8</format>
          <width>640</width>
          <height>480</height>
        </image>
        <clip>
          <near>0.3</near>
          <far>10.0</far>
        </clip>
      </camera>
      <plugin filename="libgazebo_ros_openni_kinect.so" name="torso_realsense_controller">
        <cameraName>front_rgbd_camera</cameraName>
        <alwaysOn>true</alwaysOn>
        <updateRate>10</updateRate>
        <imageTopicName>rgb/image_raw</imageTopicName>
        <depthImageTopicName>depth/image_raw</depthImageTopicName>
        <pointCloudTopicName>depth/points</pointCloudTopicName>
        <cameraInfoTopicName>rgb/camera_info</cameraInfoTopicName>
        <depthImageCameraInfoTopicName>depth/camera_info</depthImageCameraInfoTopicName>
        <frameName>/torso_realsense_camera_depth_optical_frame</frameName>
        <baseline>0.1</baseline>
        <distortion_k1>0.0</distortion_k1>
        <distortion_k2>0.0</distortion_k2>
        <distortion_k3>0.0</distortion_k3>
        <distortion_t1>0.0</distortion_t1>
        <distortion_t2>0.0</distortion_t2>
        <pointCloudCutoff>0.4</pointCloudCutoff>
      </plugin>
    </sensor>
  </gazebo>
  <!--xacro:sensor_ueye_cp_gige prefix="${prefix}torso_ueye_left" parent="${prefix}torso_pantilt_link">
            <origin xyz="0.0258 -0.14975 0.0165" rpy="0 0 0"/>
        </xacro:sensor_ueye_cp_gige> 
        
        <xacro:sensor_ueye_cp_gige prefix="${prefix}torso_ueye_right" parent="${prefix}torso_pantilt_link">
            <origin xyz="0.0258 0.14975 0.0165" rpy="0 0 0"/>
        </xacro:sensor_ueye_cp_gige-->
  <!-- Fix right arm to torso -->
  <joint name="torso_right_arm_base_joint" type="fixed">
    <origin rpy="0 -0.785398163397 -1.57079632679" xyz="0.16870 0.28753 -0.12303"/>
    <parent link="torso_guidance_elevation_link"/>
    <child link="right_arm_base_link"/>
  </joint>
  <link name="right_arm_base_link">
    <visual>
      <geometry>
        <mesh filename="package://ur_description/meshes/ur10/visual/base.dae"/>
      </geometry>
      <material name="LightGrey">
        <color rgba="0.7 0.7 0.7 1.0"/>
      </material>
    </visual>
    <collision>
      <geometry>
        <mesh filename="package://ur_description/meshes/ur10/collision/base.stl"/>
      </geometry>
    </collision>
    <inertial>
      <mass value="4.0"/>
      <origin rpy="0 0 0" xyz="0.0 0.0 0.0"/>
      <inertia ixx="0.0061063308908" ixy="0.0" ixz="0.0" iyy="0.0061063308908" iyz="0.0" izz="0.01125"/>
    </inertial>
  </link>
  <joint name="right_arm_shoulder_pan_joint" type="revolute">
    <parent link="right_arm_base_link"/>
    <child link="right_arm_shoulder_link"/>
    <origin rpy="0.0 0.0 0.0" xyz="0.0 0.0 0.1273"/>
    <axis xyz="0 0 1"/>
    <limit effort="330.0" lower="-3.14159265359" upper="3.14159265359" velocity="2.16"/>
    <dynamics damping="0.0" friction="0.0"/>
  </joint>
  <link name="right_arm_shoulder_link">
    <visual>
      <geometry>
        <mesh filename="package://ur_description/meshes/ur10/visual/shoulder.dae"/>
      </geometry>
      <material name="LightGrey">
        <color rgba="0.7 0.7 0.7 1.0"/>
      </material>
    </visual>
    <collision>
      <geometry>
        <mesh filename="package://ur_description/meshes/ur10/collision/shoulder.stl"/>
      </geometry>
    </collision>
    <inertial>
      <mass value="7.778"/>
      <origin rpy="0 0 0" xyz="0.0 0.0 0.0"/>
      <inertia ixx="0.0314743125769" ixy="0.0" ixz="0.0" iyy="0.0314743125769" iyz="0.0" izz="0.021875625"/>
    </inertial>
  </link>
  <joint name="right_arm_shoulder_lift_joint" type="revolute">
    <parent link="right_arm_shoulder_link"/>
    <child link="right_arm_upper_arm_link"/>
    <origin rpy="0.0 1.57079632679 0.0" xyz="0.0 0.220941 0.0"/>
    <axis xyz="0 1 0"/>
    <limit effort="330.0" lower="-3.14159265359" upper="3.14159265359" velocity="2.16"/>
    <dynamics damping="0.0" friction="0.0"/>
  </joint>
  <link name="right_arm_upper_arm_link">
    <visual>
      <geometry>
        <mesh filename="package://ur_description/meshes/ur10/visual/upperarm.dae"/>
      </geometry>
      <material name="LightGrey">
        <color rgba="0.7 0.7 0.7 1.0"/>
      </material>
    </visual>
    <collision>
      <geometry>
        <mesh filename="package://ur_description/meshes/ur10/collision/upperarm.stl"/>
      </geometry>
    </collision>
    <inertial>
      <mass value="12.93"/>
      <origin rpy="0 0 0" xyz="0.0 0.0 0.306"/>
      <inertia ixx="0.421753803798" ixy="0.0" ixz="0.0" iyy="0.421753803798" iyz="0.0" izz="0.036365625"/>
    </inertial>
  </link>
  <joint name="right_arm_elbow_joint" type="revolute">
    <parent link="right_arm_upper_arm_link"/>
    <child link="right_arm_forearm_link"/>
    <origin rpy="0.0 0.0 0.0" xyz="0.0 -0.1719 0.612"/>
    <axis xyz="0 1 0"/>
    <limit effort="150.0" lower="-3.14159265359" upper="3.14159265359" velocity="3.15"/>
    <dynamics damping="0.0" friction="0.0"/>
  </joint>
  <link name="right_arm_forearm_link">
    <visual>
      <geometry>
        <mesh filename="package://ur_description/meshes/ur10/visual/forearm.dae"/>
      </geometry>
      <material name="LightGrey">
        <color rgba="0.7 0.7 0.7 1.0"/>
      </material>
    </visual>
    <collision>
      <geometry>
        <mesh filename="package://ur_description/meshes/ur10/collision/forearm.stl"/>
      </geometry>
    </collision>
    <inertial>
      <mass value="3.87"/>
      <origin rpy="0 0 0" xyz="0.0 0.0 0.28615"/>
      <inertia ixx="0.111069694097" ixy="0.0" ixz="0.0" iyy="0.111069694097" iyz="0.0" izz="0.010884375"/>
    </inertial>
  </link>
  <joint name="right_arm_wrist_1_joint" type="revolute">
    <parent link="right_arm_forearm_link"/>
    <child link="right_arm_wrist_1_link"/>
    <origin rpy="0.0 1.57079632679 0.0" xyz="0.0 0.0 0.5723"/>
    <axis xyz="0 1 0"/>
    <limit effort="54.0" lower="-3.14159265359" upper="3.14159265359" velocity="3.2"/>
    <dynamics damping="0.0" friction="0.0"/>
  </joint>
  <link name="right_arm_wrist_1_link">
    <visual>
      <geometry>
        <mesh filename="package://ur_description/meshes/ur10/visual/wrist1.dae"/>
      </geometry>
      <material name="LightGrey">
        <color rgba="0.7 0.7 0.7 1.0"/>
      </material>
    </visual>
    <collision>
      <geometry>
        <mesh filename="package://ur_description/meshes/ur10/collision/wrist1.stl"/>
      </geometry>
    </collision>
    <inertial>
      <mass value="1.96"/>
      <origin rpy="0 0 0" xyz="0.0 0.0 0.0"/>
      <inertia ixx="0.0051082479567" ixy="0.0" ixz="0.0" iyy="0.0051082479567" iyz="0.0" izz="0.0055125"/>
    </inertial>
  </link>
  <joint name="right_arm_wrist_2_joint" type="revolute">
    <parent link="right_arm_wrist_1_link"/>
    <child link="right_arm_wrist_2_link"/>
    <origin rpy="0.0 0.0 0.0" xyz="0.0 0.1149 0.0"/>
    <axis xyz="0 0 1"/>
    <limit effort="54.0" lower="-3.14159265359" upper="3.14159265359" velocity="3.2"/>
    <dynamics damping="0.0" friction="0.0"/>
  </joint>
  <link name="right_arm_wrist_2_link">
    <visual>
      <geometry>
        <mesh filename="package://ur_description/meshes/ur10/visual/wrist2.dae"/>
      </geometry>
      <material name="LightGrey">
        <color rgba="0.7 0.7 0.7 1.0"/>
      </material>
    </visual>
    <collision>
      <geometry>
        <mesh filename="package://ur_description/meshes/ur10/collision/wrist2.stl"/>
      </geometry>
    </collision>
    <inertial>
      <mass value="1.96"/>
      <origin rpy="0 0 0" xyz="0.0 0.0 0.0"/>
      <inertia ixx="0.0051082479567" ixy="0.0" ixz="0.0" iyy="0.0051082479567" iyz="0.0" izz="0.0055125"/>
    </inertial>
  </link>
  <joint name="right_arm_wrist_3_joint" type="revolute">
    <parent link="right_arm_wrist_2_link"/>
    <child link="right_arm_wrist_3_link"/>
    <origin rpy="0.0 0.0 0.0" xyz="0.0 0.0 0.1157"/>
    <axis xyz="0 1 0"/>
    <limit effort="54.0" lower="-3.14159265359" upper="3.14159265359" velocity="3.2"/>
    <dynamics damping="0.0" friction="0.0"/>
  </joint>
  <link name="right_arm_wrist_3_link">
    <visual>
      <geometry>
        <mesh filename="package://ur_description/meshes/ur10/visual/wrist3.dae"/>
      </geometry>
      <material name="LightGrey">
        <color rgba="0.7 0.7 0.7 1.0"/>
      </material>
    </visual>
    <collision>
      <geometry>
        <mesh filename="package://ur_description/meshes/ur10/collision/wrist3.stl"/>
      </geometry>
    </collision>
    <inertial>
      <mass value="0.202"/>
      <origin rpy="0 0 0" xyz="0.0 0.0 0.0"/>
      <inertia ixx="0.000526462289415" ixy="0.0" ixz="0.0" iyy="0.000526462289415" iyz="0.0" izz="0.000568125"/>
    </inertial>
  </link>
  <joint name="right_arm_ee_fixed_joint" type="fixed">
    <parent link="right_arm_wrist_3_link"/>
    <child link="right_arm_ee_link"/>
    <origin rpy="0.0 0.0 1.57079632679" xyz="0.0 0.0922 0.0"/>
  </joint>
  <link name="right_arm_ee_link">
    <collision>
      <geometry>
        <box size="0.01 0.01 0.01"/>
      </geometry>
      <origin rpy="0 0 0" xyz="-0.01 0 0"/>
    </collision>
  </link>
  <transmission name="right_arm_shoulder_pan_trans">
    <type>transmission_interface/SimpleTransmission</type>
    <joint name="right_arm_shoulder_pan_joint">
      <hardwareInterface>hardware_interface/PositionJointInterface</hardwareInterface>
    </joint>
    <actuator name="right_arm_shoulder_pan_motor">
      <mechanicalReduction>1</mechanicalReduction>
    </actuator>
  </transmission>
  <transmission name="right_arm_shoulder_lift_trans">
    <type>transmission_interface/SimpleTransmission</type>
    <joint name="right_arm_shoulder_lift_joint">
      <hardwareInterface>hardware_interface/PositionJointInterface</hardwareInterface>
    </joint>
    <actuator name="right_arm_shoulder_lift_motor">
      <mechanicalReduction>1</mechanicalReduction>
    </actuator>
  </transmission>
  <transmission name="right_arm_elbow_trans">
    <type>transmission_interface/SimpleTransmission</type>
    <joint name="right_arm_elbow_joint">
      <hardwareInterface>hardware_interface/PositionJointInterface</hardwareInterface>
    </joint>
    <actuator name="right_arm_elbow_motor">
      <mechanicalReduction>1</mechanicalReduction>
    </actuator>
  </transmission>
  <transmission name="right_arm_wrist_1_trans">
    <type>transmission_interface/SimpleTransmission</type>
    <joint name="right_arm_wrist_1_joint">
      <hardwareInterface>hardware_interface/PositionJointInterface</hardwareInterface>
    </joint>
    <actuator name="right_arm_wrist_1_motor">
      <mechanicalReduction>1</mechanicalReduction>
    </actuator>
  </transmission>
  <transmission name="right_arm_wrist_2_trans">
    <type>transmission_interface/SimpleTransmission</type>
    <joint name="right_arm_wrist_2_joint">
      <hardwareInterface>hardware_interface/PositionJointInterface</hardwareInterface>
    </joint>
    <actuator name="right_arm_wrist_2_motor">
      <mechanicalReduction>1</mechanicalReduction>
    </actuator>
  </transmission>
  <transmission name="right_arm_wrist_3_trans">
    <type>transmission_interface/SimpleTransmission</type>
    <joint name="right_arm_wrist_3_joint">
      <hardwareInterface>hardware_interface/PositionJointInterface</hardwareInterface>
    </joint>
    <actuator name="right_arm_wrist_3_motor">
      <mechanicalReduction>1</mechanicalReduction>
    </actuator>
  </transmission>
  <!-- nothing to do here at the moment -->
  <!-- ROS base_link to UR 'Base' Coordinates transform -->
  <link name="right_arm_base"/>
  <joint name="right_arm_base_link-base_fixed_joint" type="fixed">
    <!-- NOTE: this rotation is only needed as long as base_link itself is
                 not corrected wrt the real robot (ie: rotated over 180
                 degrees)
      -->
    <origin rpy="0 0 -3.14159265359" xyz="0 0 0"/>
    <parent link="right_arm_base_link"/>
    <child link="right_arm_base"/>
  </joint>
  <!-- Frame coincident with all-zeros TCP on UR controller -->
  <link name="right_arm_tool0"/>
  <joint name="right_arm_wrist_3_link-tool0_fixed_joint" type="fixed">
    <origin rpy="-1.57079632679 0 0" xyz="0 0.0922 0"/>
    <parent link="right_arm_wrist_3_link"/>
    <child link="right_arm_tool0"/>
  </joint>
  <!-- Fix left arm to torso -->
  <joint name="torso_left_arm_base_joint" type="fixed">
    <origin rpy="0 0.785398163397 -1.57079632679" xyz="0.16870 -0.28753 -0.12303"/>
    <parent link="torso_guidance_elevation_link"/>
    <child link="left_arm_base_link"/>
  </joint>
  <link name="left_arm_base_link">
    <visual>
      <geometry>
        <mesh filename="package://ur_description/meshes/ur10/visual/base.dae"/>
      </geometry>
      <material name="LightGrey">
        <color rgba="0.7 0.7 0.7 1.0"/>
      </material>
    </visual>
    <collision>
      <geometry>
        <mesh filename="package://ur_description/meshes/ur10/collision/base.stl"/>
      </geometry>
    </collision>
    <inertial>
      <mass value="4.0"/>
      <origin rpy="0 0 0" xyz="0.0 0.0 0.0"/>
      <inertia ixx="0.0061063308908" ixy="0.0" ixz="0.0" iyy="0.0061063308908" iyz="0.0" izz="0.01125"/>
    </inertial>
  </link>
  <joint name="left_arm_shoulder_pan_joint" type="revolute">
    <parent link="left_arm_base_link"/>
    <child link="left_arm_shoulder_link"/>
    <origin rpy="0.0 0.0 0.0" xyz="0.0 0.0 0.1273"/>
    <axis xyz="0 0 1"/>
    <limit effort="330.0" lower="-3.14159265359" upper="3.14159265359" velocity="2.16"/>
    <dynamics damping="0.0" friction="0.0"/>
  </joint>
  <link name="left_arm_shoulder_link">
    <visual>
      <geometry>
        <mesh filename="package://ur_description/meshes/ur10/visual/shoulder.dae"/>
      </geometry>
      <material name="LightGrey">
        <color rgba="0.7 0.7 0.7 1.0"/>
      </material>
    </visual>
    <collision>
      <geometry>
        <mesh filename="package://ur_description/meshes/ur10/collision/shoulder.stl"/>
      </geometry>
    </collision>
    <inertial>
      <mass value="7.778"/>
      <origin rpy="0 0 0" xyz="0.0 0.0 0.0"/>
      <inertia ixx="0.0314743125769" ixy="0.0" ixz="0.0" iyy="0.0314743125769" iyz="0.0" izz="0.021875625"/>
    </inertial>
  </link>
  <joint name="left_arm_shoulder_lift_joint" type="revolute">
    <parent link="left_arm_shoulder_link"/>
    <child link="left_arm_upper_arm_link"/>
    <origin rpy="0.0 1.57079632679 0.0" xyz="0.0 0.220941 0.0"/>
    <axis xyz="0 1 0"/>
    <limit effort="330.0" lower="-3.14159265359" upper="3.14159265359" velocity="2.16"/>
    <dynamics damping="0.0" friction="0.0"/>
  </joint>
  <link name="left_arm_upper_arm_link">
    <visual>
      <geometry>
        <mesh filename="package://ur_description/meshes/ur10/visual/upperarm.dae"/>
      </geometry>
      <material name="LightGrey">
        <color rgba="0.7 0.7 0.7 1.0"/>
      </material>
    </visual>
    <collision>
      <geometry>
        <mesh filename="package://ur_description/meshes/ur10/collision/upperarm.stl"/>
      </geometry>
    </collision>
    <inertial>
      <mass value="12.93"/>
      <origin rpy="0 0 0" xyz="0.0 0.0 0.306"/>
      <inertia ixx="0.421753803798" ixy="0.0" ixz="0.0" iyy="0.421753803798" iyz="0.0" izz="0.036365625"/>
    </inertial>
  </link>
  <joint name="left_arm_elbow_joint" type="revolute">
    <parent link="left_arm_upper_arm_link"/>
    <child link="left_arm_forearm_link"/>
    <origin rpy="0.0 0.0 0.0" xyz="0.0 -0.1719 0.612"/>
    <axis xyz="0 1 0"/>
    <limit effort="150.0" lower="-3.14159265359" upper="3.14159265359" velocity="3.15"/>
    <dynamics damping="0.0" friction="0.0"/>
  </joint>
  <link name="left_arm_forearm_link">
    <visual>
      <geometry>
        <mesh filename="package://ur_description/meshes/ur10/visual/forearm.dae"/>
      </geometry>
      <material name="LightGrey">
        <color rgba="0.7 0.7 0.7 1.0"/>
      </material>
    </visual>
    <collision>
      <geometry>
        <mesh filename="package://ur_description/meshes/ur10/collision/forearm.stl"/>
      </geometry>
    </collision>
    <inertial>
      <mass value="3.87"/>
      <origin rpy="0 0 0" xyz="0.0 0.0 0.28615"/>
      <inertia ixx="0.111069694097" ixy="0.0" ixz="0.0" iyy="0.111069694097" iyz="0.0" izz="0.010884375"/>
    </inertial>
  </link>
  <joint name="left_arm_wrist_1_joint" type="revolute">
    <parent link="left_arm_forearm_link"/>
    <child link="left_arm_wrist_1_link"/>
    <origin rpy="0.0 1.57079632679 0.0" xyz="0.0 0.0 0.5723"/>
    <axis xyz="0 1 0"/>
    <limit effort="54.0" lower="-3.14159265359" upper="3.14159265359" velocity="3.2"/>
    <dynamics damping="0.0" friction="0.0"/>
  </joint>
  <link name="left_arm_wrist_1_link">
    <visual>
      <geometry>
        <mesh filename="package://ur_description/meshes/ur10/visual/wrist1.dae"/>
      </geometry>
      <material name="LightGrey">
        <color rgba="0.7 0.7 0.7 1.0"/>
      </material>
    </visual>
    <collision>
      <geometry>
        <mesh filename="package://ur_description/meshes/ur10/collision/wrist1.stl"/>
      </geometry>
    </collision>
    <inertial>
      <mass value="1.96"/>
      <origin rpy="0 0 0" xyz="0.0 0.0 0.0"/>
      <inertia ixx="0.0051082479567" ixy="0.0" ixz="0.0" iyy="0.0051082479567" iyz="0.0" izz="0.0055125"/>
    </inertial>
  </link>
  <joint name="left_arm_wrist_2_joint" type="revolute">
    <parent link="left_arm_wrist_1_link"/>
    <child link="left_arm_wrist_2_link"/>
    <origin rpy="0.0 0.0 0.0" xyz="0.0 0.1149 0.0"/>
    <axis xyz="0 0 1"/>
    <limit effort="54.0" lower="-3.14159265359" upper="3.14159265359" velocity="3.2"/>
    <dynamics damping="0.0" friction="0.0"/>
  </joint>
  <link name="left_arm_wrist_2_link">
    <visual>
      <geometry>
        <mesh filename="package://ur_description/meshes/ur10/visual/wrist2.dae"/>
      </geometry>
      <material name="LightGrey">
        <color rgba="0.7 0.7 0.7 1.0"/>
      </material>
    </visual>
    <collision>
      <geometry>
        <mesh filename="package://ur_description/meshes/ur10/collision/wrist2.stl"/>
      </geometry>
    </collision>
    <inertial>
      <mass value="1.96"/>
      <origin rpy="0 0 0" xyz="0.0 0.0 0.0"/>
      <inertia ixx="0.0051082479567" ixy="0.0" ixz="0.0" iyy="0.0051082479567" iyz="0.0" izz="0.0055125"/>
    </inertial>
  </link>
  <joint name="left_arm_wrist_3_joint" type="revolute">
    <parent link="left_arm_wrist_2_link"/>
    <child link="left_arm_wrist_3_link"/>
    <origin rpy="0.0 0.0 0.0" xyz="0.0 0.0 0.1157"/>
    <axis xyz="0 1 0"/>
    <limit effort="54.0" lower="-3.14159265359" upper="3.14159265359" velocity="3.2"/>
    <dynamics damping="0.0" friction="0.0"/>
  </joint>
  <link name="left_arm_wrist_3_link">
    <visual>
      <geometry>
        <mesh filename="package://ur_description/meshes/ur10/visual/wrist3.dae"/>
      </geometry>
      <material name="LightGrey">
        <color rgba="0.7 0.7 0.7 1.0"/>
      </material>
    </visual>
    <collision>
      <geometry>
        <mesh filename="package://ur_description/meshes/ur10/collision/wrist3.stl"/>
      </geometry>
    </collision>
    <inertial>
      <mass value="0.202"/>
      <origin rpy="0 0 0" xyz="0.0 0.0 0.0"/>
      <inertia ixx="0.000526462289415" ixy="0.0" ixz="0.0" iyy="0.000526462289415" iyz="0.0" izz="0.000568125"/>
    </inertial>
  </link>
  <joint name="left_arm_ee_fixed_joint" type="fixed">
    <parent link="left_arm_wrist_3_link"/>
    <child link="left_arm_ee_link"/>
    <origin rpy="0.0 0.0 1.57079632679" xyz="0.0 0.0922 0.0"/>
  </joint>
  <link name="left_arm_ee_link">
    <collision>
      <geometry>
        <box size="0.01 0.01 0.01"/>
      </geometry>
      <origin rpy="0 0 0" xyz="-0.01 0 0"/>
    </collision>
  </link>
  <transmission name="left_arm_shoulder_pan_trans">
    <type>transmission_interface/SimpleTransmission</type>
    <joint name="left_arm_shoulder_pan_joint">
      <hardwareInterface>hardware_interface/PositionJointInterface</hardwareInterface>
    </joint>
    <actuator name="left_arm_shoulder_pan_motor">
      <mechanicalReduction>1</mechanicalReduction>
    </actuator>
  </transmission>
  <transmission name="left_arm_shoulder_lift_trans">
    <type>transmission_interface/SimpleTransmission</type>
    <joint name="left_arm_shoulder_lift_joint">
      <hardwareInterface>hardware_interface/PositionJointInterface</hardwareInterface>
    </joint>
    <actuator name="left_arm_shoulder_lift_motor">
      <mechanicalReduction>1</mechanicalReduction>
    </actuator>
  </transmission>
  <transmission name="left_arm_elbow_trans">
    <type>transmission_interface/SimpleTransmission</type>
    <joint name="left_arm_elbow_joint">
      <hardwareInterface>hardware_interface/PositionJointInterface</hardwareInterface>
    </joint>
    <actuator name="left_arm_elbow_motor">
      <mechanicalReduction>1</mechanicalReduction>
    </actuator>
  </transmission>
  <transmission name="left_arm_wrist_1_trans">
    <type>transmission_interface/SimpleTransmission</type>
    <joint name="left_arm_wrist_1_joint">
      <hardwareInterface>hardware_interface/PositionJointInterface</hardwareInterface>
    </joint>
    <actuator name="left_arm_wrist_1_motor">
      <mechanicalReduction>1</mechanicalReduction>
    </actuator>
  </transmission>
  <transmission name="left_arm_wrist_2_trans">
    <type>transmission_interface/SimpleTransmission</type>
    <joint name="left_arm_wrist_2_joint">
      <hardwareInterface>hardware_interface/PositionJointInterface</hardwareInterface>
    </joint>
    <actuator name="left_arm_wrist_2_motor">
      <mechanicalReduction>1</mechanicalReduction>
    </actuator>
  </transmission>
  <transmission name="left_arm_wrist_3_trans">
    <type>transmission_interface/SimpleTransmission</type>
    <joint name="left_arm_wrist_3_joint">
      <hardwareInterface>hardware_interface/PositionJointInterface</hardwareInterface>
    </joint>
    <actuator name="left_arm_wrist_3_motor">
      <mechanicalReduction>1</mechanicalReduction>
    </actuator>
  </transmission>
  <!-- nothing to do here at the moment -->
  <!-- ROS base_link to UR 'Base' Coordinates transform -->
  <link name="left_arm_base"/>
  <joint name="left_arm_base_link-base_fixed_joint" type="fixed">
    <!-- NOTE: this rotation is only needed as long as base_link itself is
                 not corrected wrt the real robot (ie: rotated over 180
                 degrees)
      -->
    <origin rpy="0 0 -3.14159265359" xyz="0 0 0"/>
    <parent link="left_arm_base_link"/>
    <child link="left_arm_base"/>
  </joint>
  <!-- Frame coincident with all-zeros TCP on UR controller -->
  <link name="left_arm_tool0"/>
  <joint name="left_arm_wrist_3_link-tool0_fixed_joint" type="fixed">
    <origin rpy="-1.57079632679 0 0" xyz="0 0.0922 0"/>
    <parent link="left_arm_wrist_3_link"/>
    <child link="left_arm_tool0"/>
  </joint>
  <joint name="left_arm_ee_tube_support_joint" type="fixed">
    <origin rpy="0 0 0" xyz="0.012 0 0.0975"/>
    <parent link="left_arm_ee_link"/>
    <child link="left_arm_ee_tube_support_link"/>
  </joint>
  <link name="left_arm_ee_tube_support_link">
    <collision>
      <origin rpy="0 0 0" xyz="0 0 0"/>
      <geometry>
        <box size="0.075 0.075 0.075"/>
      </geometry>
    </collision>
    <!--<inertial>-->
    <!--<mass value="0.1" />-->
    <!--<origin xyz="0 0 0" />-->
    <!--<inertia  ixx="1" ixy="0.0"  ixz="0.0"  iyy="1"  iyz="0.0"  izz="1" />-->
    <!--</inertial>    -->
  </link>
  <joint name="right_arm_ee_tube_support_joint" type="fixed">
    <origin rpy="0 0 0" xyz="0.012 0 0.0975"/>
    <parent link="right_arm_ee_link"/>
    <child link="right_arm_ee_tube_support_link"/>
  </joint>
  <link name="right_arm_ee_tube_support_link">
    <collision>
      <origin rpy="0 0 0" xyz="0 0 0"/>
      <geometry>
        <box size="0.075 0.075 0.075"/>
      </geometry>
    </collision>
    <!--<inertial>-->
    <!--<mass value="0.1" />-->
    <!--<origin xyz="0 0 0" />-->
    <!--<inertia  ixx="1" ixy="0.0"  ixz="0.0"  iyy="1"  iyz="0.0"  izz="1" />-->
    <!--</inertial>    -->
  </link>
  <!-- params="ns"> -->
  <gazebo>
    <plugin filename="libgazebo_ros_control.so" name="ros_control">
      <!--<robotNamespace>${ns}</robotNamespace>-->
      <!--<robotParam>robot_description</robotParam>-->
      <controlPeriod>0.001</controlPeriod>
      <robotSimType>gazebo_ros_control/DefaultRobotHWSim</robotSimType>
    </plugin>
  </gazebo>
</robot>

