<?xml version="1.0"?>
<robot xmlns:xacro="http://ros.org/wiki/xacro">
  <xacro:property name="PI" value="3.1415926535897931"/>
  <xacro:property name="deg2rad" value="0.01745329251"/>
  <xacro:property name="elevation_max_longitude" value="0.7"/>
  <xacro:property name="z_elevation_joint" value="0.442"/>
  <!-- Define the torso -->
  <xacro:macro name="guidance" params="prefix parent hq">
    <joint name="${prefix}torso_guidance_base_joint" type="fixed">
      <origin xyz="0.0 0.0 0.0" rpy="0 0 0"/>
      <parent link="${parent}"/>
      <child link="${prefix}torso_guidance_base_link"/>
      <axis xyz="0 0 1"/>
    </joint>
    
    <link name="${prefix}torso_guidance_base_link"/>
        
    <joint name="${prefix}torso_guidance_revolution_joint" type="revolute">
      <origin xyz="0 0 0" rpy="0 0 ${PI}"/>
      <parent link="${prefix}torso_guidance_base_link"/>
      <child link="${prefix}torso_guidance_revolution_link"/>
      <axis xyz="0 0 1"/>
      <limit lower="${-140*deg2rad}" upper="${220*deg2rad}" effort="100" velocity="0.4"/>
      <dynamics friction="1000" damping="1000"/>
    </joint>
    
	<transmission name="${prefix}torso_guidance_revolution_trans">
      <type>transmission_interface/SimpleTransmission</type>
      <joint name="${prefix}torso_guidance_revolution_joint">
        <hardwareInterface>PositionJointInterface</hardwareInterface> 
      </joint>
      <actuator name="${prefix}torso_guidance_revolution_motor">
        <mechanicalReduction>1</mechanicalReduction>
      </actuator>
    </transmission>

    
    <link name="${prefix}torso_guidance_revolution_link">
      <visual>
        <origin xyz="0 0 0" rpy="0 0 0"/>
        <geometry>
          <mesh filename="package://vulcano_torso_description/meshes/guidance/guidance.stl"/>
        </geometry>
       <material name="darkgrey">
         <color rgba="0.1 0.1 0.1 1"/>
       </material>
      </visual>
      <collision>
        <origin xyz="0 0 0" rpy="0 0 0"/>
        <geometry>
          <mesh filename="package://vulcano_torso_description/meshes/guidance/guidance.stl"/>
        </geometry>
      </collision>
      <inertial>
        <origin xyz="0.011 -0.001 0.623" rpy="0 0 0"/>
        <mass value="128"/>
        <inertia ixx="29.075" ixy="0.013" ixz="0.582" iyy="28.51" iyz="0.009" izz="1.37"/>
      </inertial>
    </link>
    
    <joint name="${prefix}torso_guidance_elevation_joint" type="prismatic">
      <origin xyz="-0.1687 0 0.720" rpy="0 0 0"/>
      <parent link="${prefix}torso_guidance_revolution_link"/>
      <child link="${prefix}torso_guidance_elevation_link"/>
      <axis xyz="0 0 1"/>
      <limit lower="0.0" upper="0.6" effort="100" velocity="0.08"/>
      <dynamics friction="100000" damping="10000"/>
    </joint>

	<transmission name="${prefix}torso_guidance_elevation_trans"> 
      <type>transmission_interface/SimpleTransmission</type>
      <joint name="${prefix}torso_guidance_elevation_joint">
        <hardwareInterface>PositionJointInterface</hardwareInterface> 
      </joint>
      <actuator name="${prefix}torso_guidance_elevation_motor">
        <mechanicalReduction>1</mechanicalReduction>
      </actuator>
    </transmission>
    
    <link name="${prefix}torso_guidance_elevation_link">
      <visual>
        <origin xyz="0 0 0" rpy="0 0 0"/>
        <geometry>
          <mesh filename="package://vulcano_torso_description/meshes/guidance/slide.stl"/>
        </geometry>
       <material name="darkgrey">
         <color rgba="0.1 0.1 0.1 1"/>
       </material>
      </visual>
      <collision>
        <origin xyz="0 0 0" rpy="0 0 0"/>
        <geometry>
          <mesh filename="package://vulcano_torso_description/meshes/guidance/slide.stl"/>
        </geometry>
      </collision>
      <inertial>
        <origin xyz="0.05 0.001 0.432" rpy="0 0 0"/>
        <mass value="41"/>
        <inertia ixx="1.881" ixy="-0.004" ixz="0.084" iyy="1.122" iyz="-0.008" izz="1.295"/>
      </inertial>
    </link>
  
  </xacro:macro>
</robot>
