<?xml version="1.0"?>
<robot xmlns:xacro="http://ros.org/wiki/xacro">
  <xacro:property name="PI" value="3.1415926535897931"/>
  <xacro:property name="deg2rad" value="0.01745329251"/>
  <xacro:property name="elevation_max_longitude" value="0.7"/>
  <xacro:property name="z_elevation_joint" value="0.442"/>
  <!-- Define the torso -->
  <xacro:macro name="guidance" params="prefix parent hq">
    <joint name="${prefix}torso_guidance_base_joint" type="fixed">
      <origin xyz="0.0 0.0 0.0" rpy="0 0 0"/>
      <parent link="${parent}"/>
      <child link="${prefix}torso_guidance_base_link"/>
      <axis xyz="0 0 1"/>
    </joint>
    
    <link name="${prefix}torso_guidance_base_link">
      <visual>
        <origin xyz="0 0 0" rpy="0 0 0"/>
        <geometry>
          <mesh filename="package://vulcano_torso_description/meshes/guidance/base.stl"/>
        </geometry>
       <material name="darkgrey">
         <color rgba="0.1 0.1 0.1 1"/>
       </material>
      </visual>
      <collision>
        <origin xyz="0 0 0" rpy="0 0 0"/>
        <geometry>
          <mesh filename="package://vulcano_torso_description/meshes/guidance/base.stl"/>
        </geometry>
      </collision>
      <inertial>
        <origin xyz="0 0 0" rpy="0 0 0"/>
        <mass value="5"/>
        <inertia ixx="1.0" ixy="0.0" ixz="0.0" iyy="1.0" iyz="0.0" izz="1.0"/>
      </inertial>
    </link>
    
    <joint name="${prefix}torso_guidance_revolution_joint" type="revolute">
      <origin xyz="0 0 0" rpy="0 0 ${PI}"/>
      <parent link="${prefix}torso_guidance_base_link"/>
      <child link="${prefix}torso_guidance_revolution_link"/>
      <axis xyz="0 0 1"/>
      <limit lower="${-180*deg2rad}" upper="${180*deg2rad}" effort="100" velocity="100"/>
      <dynamics friction="1000" damping="1000"/>
    </joint>
    
	<transmission name="${prefix}torso_guidance_revolution_trans">
      <type>transmission_interface/SimpleTransmission</type>
      <joint name="${prefix}torso_guidance_revolution_joint">
        <hardwareInterface>PositionJointInterface</hardwareInterface> 
      </joint>
      <actuator name="${prefix}torso_guidance_revolution_motor">
        <mechanicalReduction>1</mechanicalReduction>
      </actuator>
    </transmission>

    
    <link name="${prefix}torso_guidance_revolution_link">
      <visual>
        <origin xyz="0 0 0" rpy="0 0 0"/>
        <geometry>
          <mesh filename="package://vulcano_torso_description/meshes/guidance/main.stl"/>
        </geometry>
       <material name="darkgrey">
         <color rgba="0.1 0.1 0.1 1"/>
       </material>
      </visual>
      <collision>
        <origin xyz="0 0 0" rpy="0 0 0"/>
        <geometry>
          <mesh filename="package://vulcano_torso_description/meshes/guidance/main.stl"/>
        </geometry>
      </collision>
      <inertial>
        <origin xyz="0 0 0" rpy="0 0 0"/>
        <mass value="5"/>
        <inertia ixx="1.0" ixy="0.0" ixz="0.0" iyy="1.0" iyz="0.0" izz="1.0"/>
      </inertial>
    </link>
    
    <joint name="${prefix}torso_guidance_elevation_joint" type="prismatic">
      <origin xyz="0 0 0.115" rpy="0 0 0"/>
      <parent link="${prefix}torso_guidance_revolution_link"/>
      <child link="${prefix}torso_guidance_elevation_link"/>
      <axis xyz="0 0 1"/>
      <limit lower="0.0" upper="0.68" effort="100" velocity="100"/>
      <dynamics friction="100000" damping="10000"/>
    </joint>

	<transmission name="${prefix}torso_guidance_elevation_trans"> 
      <type>transmission_interface/SimpleTransmission</type>
      <joint name="${prefix}torso_guidance_elevation_joint">
        <hardwareInterface>PositionJointInterface</hardwareInterface> 
      </joint>
      <actuator name="${prefix}torso_guidance_elevation_motor">
        <mechanicalReduction>1</mechanicalReduction>
      </actuator>
    </transmission>
    
    <link name="${prefix}torso_guidance_elevation_link">
      <visual>
        <origin xyz="0 0 0" rpy="0 0 0"/>
        <geometry>
          <mesh filename="package://vulcano_torso_description/meshes/guidance/slide.stl"/>
        </geometry>
       <material name="darkgrey">
         <color rgba="0.1 0.1 0.1 1"/>
       </material>
      </visual>
      <collision>
        <origin xyz="0 0 0" rpy="0 0 0"/>
        <geometry>
          <mesh filename="package://vulcano_torso_description/meshes/guidance/slide.stl"/>
        </geometry>
      </collision>
      <inertial>
        <origin xyz="0 0 0" rpy="0 0 0"/>
        <mass value="1"/>
        <inertia ixx="1.0" ixy="0.0" ixz="0.0" iyy="1.0" iyz="0.0" izz="1.0"/>
      </inertial>
    </link>
    
    <joint name="${prefix}torso_tkd668_joint" type="fixed">
      <origin xyz="0.164 0 0.449" rpy="0 0 0"/>
      <parent link="${prefix}torso_guidance_elevation_link"/>
      <child link="${prefix}torso_tkd668_link"/>
      <axis xyz="0 0 1"/>
    </joint>
    
    <link name="${prefix}torso_tkd668_link">
      <visual>
        <origin xyz="0 0 0" rpy="0 0 0"/>
        <geometry>
          <mesh filename="package://vulcano_torso_description/meshes/guidance/tkd668.stl"/>
        </geometry>
       <material name="darkgrey">
         <color rgba="0.1 0.1 0.1 1"/>
       </material>
      </visual>
      <collision>
        <origin xyz="0 0 0" rpy="0 0 0"/>
        <geometry>
          <mesh filename="package://vulcano_torso_description/meshes/guidance/tkd668.stl"/>
        </geometry>
      </collision>
    </link>
  
  </xacro:macro>
</robot>
