<?xml version="1.0"?>
<robot xmlns:xacro="http://www.ros.org/wiki/xacro">

  <xacro:property name="M_PI" value="3.1415926535897931" />
  <!-- Wheels -->
  <property name="wheel_radius" value="0.093" /> 
  <property name="wheel_height" value="0.14" />
  <property name="wheel_mass" value="5.0" /> <!-- in kg-->
  
  <xacro:property name="steer_joint_damping" value="2.0" />
  <xacro:property name="steer_joint_friction" value="1.0" />
  <xacro:property name="steer_joint_effort_limit" value="100.0" />
  <xacro:property name="steer_joint_velocity_limit" value="2" />
  <xacro:property name="steer_joint_position_limit" value="2.8" /> 
  <xacro:property name="motor_wheel_mechanical_reduction" value="1.0" />

  <xacro:property name="wheel_joint_damping" value="0.1" />
  <xacro:property name="wheel_joint_friction" value="0.1" />
  <xacro:property name="wheel_joint_effort_limit" value="1000.0" />
  <xacro:property name="wheel_joint_velocity_limit" value="2000.0" />
  <xacro:property name="wheel_mechanical_reduction" value="1.0" />
     
  <xacro:macro name="cylinder_inertia" params="m r h">
    <inertia  ixx="${m*(3*r*r+h*h)/12}" ixy = "0" ixz = "0"
              iyy="${m*(3*r*r+h*h)/12}" iyz = "0"
              izz="${m*r*r/2}" /> 
  </xacro:macro>
 
  <xacro:macro name="motor_wheel" params="prefix parent *origin reflect hq">
  <!-- TODO: check reflect parameter -->
  <!--MOTOR WHEEL -->  
    <joint name="${prefix}motor_wheel_joint" type="revolute">
      <parent link="${parent}"/>
      <child link="${prefix}motor_wheel"/>
      <insert_block name="origin" />
      <axis xyz="0 0 1" rpy="0 0 0" />
      <limit effort="${steer_joint_effort_limit}" velocity="${steer_joint_velocity_limit}" lower="-${steer_joint_position_limit}" upper="${steer_joint_position_limit}"/>
      <joint_properties damping="${steer_joint_damping}" friction="${steer_joint_friction}"/>
    </joint>
      
     
  <transmission name="${prefix}motor_wheel_trans">
     <type>transmission_interface/SimpleTransmission</type>
     <joint name="${prefix}motor_wheel_joint">
        <hardwareInterface>PositionJointInterface</hardwareInterface>
     </joint>
     <actuator name="${prefix}motor_wheel_motor">
        <hardwareInterface>PositionActuatorInterface</hardwareInterface>
        <mechanicalReduction>${motor_wheel_mechanical_reduction}</mechanicalReduction>
     </actuator>
  </transmission>
  <link name="${prefix}motor_wheel">
      <visual>
        <!-- HIGH RESOLUTION WHEELS -->
        <xacro:if value="${hq}">
          <origin xyz="0 0 0" rpy="0 0 0" />
          <geometry>     
                <xacro:if value="${reflect}">
                    <mesh filename="package://vulcano_base_description/meshes/wheels/motorwheel_2.dae" />
                </xacro:if>
                <xacro:unless value="${reflect}">
                    <mesh filename="package://vulcano_base_description/meshes/wheels/motorwheel_2.dae" />
                </xacro:unless>
          </geometry>         
        </xacro:if>
       <!-- LOW RESOLUTION WHEELS -->
        <xacro:unless value="${hq}">
          <origin xyz="0 0 0" rpy="0 0 0" />
          <geometry>     
                <xacro:if value="${reflect}">
                    <mesh filename="package://vulcano_base_description/meshes/wheels/motorwheel_2.stl" />
                </xacro:if>
                <xacro:unless value="${reflect}">
                    <mesh filename="package://vulcano_base_description/meshes/wheels/motorwheel_2.stl" />
                </xacro:unless>
          </geometry>         
        </xacro:unless>
      </visual>
      
      <collision>
        <origin xyz="0 0 0" rpy="0 0 0" />
        <geometry>
                <xacro:if value="${reflect}">
                    <mesh filename="package://vulcano_base_description/meshes/wheels/motorwheel_2.dae" />
                </xacro:if>
                <xacro:unless value="${reflect}">
                    <mesh filename="package://vulcano_base_description/meshes/wheels/motorwheel_2.dae" />
                </xacro:unless>
        </geometry>
      </collision>    
      <inertial>
        <mass value="10" />
        <origin xyz="0 0 0" />
        <inertia  ixx="0.01" ixy="0.0"  ixz="0.0"  iyy="0.01"  iyz="0.0"  izz="0.01" />
      </inertial>    
    </link>


   <!--WHEEL TIRE -->
   <joint name="${prefix}wheel_joint" type="continuous">
        <parent link="${prefix}motor_wheel"/>
        <child link="${prefix}wheel"/>
        <origin xyz="0 0 0" rpy="0 0 ${M_PI}" /> 
        <axis xyz="0 1 0" rpy="0 0 0" />
        <limit effort="${wheel_joint_effort_limit}" velocity="${wheel_joint_velocity_limit}"/>      
        <joint_properties damping="${wheel_joint_damping}" friction="{wheel_joint_friction}"/>
    </joint>

    <transmission name="${prefix}wheel_trans">
     <type>transmission_interface/SimpleTransmission</type>
     <joint name="${prefix}wheel_joint">
        <hardwareInterface>VelocityJointInterface</hardwareInterface>
     </joint>
     <actuator name="${prefix}wheel_motor">
       <hardwareInterface>VelocityActuatorInterface</hardwareInterface>
       <mechanicalReduction>${wheel_mechanical_reduction}</mechanicalReduction>
     </actuator>
    </transmission>
  
  <link name="${prefix}wheel">
      <visual>
        <!-- HIGH RESOLUTION WHEELS -->
        <xacro:if value="${hq}">
          <origin xyz="0 0 0" rpy="0 0 0" />
          <geometry>     
                <xacro:if value="${reflect}">
                    <mesh filename="package://vulcano_base_description/meshes/wheels/wheel_1.dae" />
                </xacro:if>
                <xacro:unless value="${reflect}">
                    <mesh filename="package://vulcano_base_description/meshes/wheels/wheel_1.dae" />
                </xacro:unless>
          </geometry>         
        </xacro:if>
       <!-- LOW RESOLUTION WHEELS -->
        <xacro:unless value="${hq}">
          <origin xyz="0 0 0" rpy="${M_PI/2} 0 0" />
          <geometry>           
            <cylinder length="${wheel_height}" radius="${wheel_radius}" />
          </geometry>      
        </xacro:unless>
      </visual>      
      <collision>
        <origin xyz="0 0 0" rpy="${M_PI/2} 0 0" />
        <geometry>
          <!--<xacro:if value="${reflect}">-->
              <!--<mesh filename="package://vulcano_base_description/meshes/wheels/wheel_1.dae" />-->
          <!--</xacro:if>-->
          <!--<xacro:unless value="${reflect}">-->
              <!--<mesh filename="package://vulcano_base_description/meshes/wheels/wheel_1.dae" />-->
          <!--</xacro:unless>-->
          <!-- cylinder length="${wheel_height}" radius="${wheel_radius}" / -->
          <sphere radius="${wheel_radius}" />
        </geometry>
      </collision>    
      <inertial>
        <mass value="${wheel_mass}" />
        <origin xyz="0 0 0" />
        <cylinder_inertia  m="${wheel_mass}" r="${wheel_radius}" h="${wheel_height}" />
      </inertial>
   </link>

    
   <!-- gazebo reference="${prefix}wheel">
        <mu1 value="1.0"/>
        <mu2 value="1.0"/>
        <kp value="10000000.0" />
        <kd value="1.0" />
        <fdir1 value="1 0 0"/>
        <turnGravityOff>false</turnGravityOff>
   </gazebo -->
       
  </xacro:macro>

</robot>
